<?xml version="1.0"?>

<robot name="robi" xmlns:xacro="http://www.ros.org/wiki/xacro">

	<link name="base_footprint"/>  

	<link name="base_link"> 
		<visual>
			<origin xyz="0 0 0.08"/>
			<geometry>
				<box size="0.30 0.24 0.13"/>
			</geometry>
		</visual>
		<collision>
			<origin xyz="0 0 0"/>
			<geometry>
				<box size="0.30 0.24 0.13"/>
			</geometry>
		</collision>
	</link>
	
	<!-- Primer Joint -->

	<joint name="base_joint" type="fixed"> 
		<parent link="base_footprint"/>
		<child link="base_link"/>
		<origin xyz="0 0 0.06"/>
	</joint>

	<link name="laser"> 
		<visual>
			<origin xyz="0 0 0" rpy="0 0 0"/>
			<geometry>
				<cylinder radius="0.035" length="0.04"/>
			</geometry>
		</visual>
		<collision>
			<origin xyz="0 0 0"/>
			<geometry>
				<cylinder radius="0.035" length="0.04"/>
			</geometry>
		</collision>
	</link>

	<joint name="base_scan_joint" type="fixed"> 
		<parent link="base_link"/>
		<child link="laser"/>
		<origin xyz="0 0 0.15 " rpy="0 0 0"/>
	</joint>

	<!-- Rueda Derecha -->

	<link name="right_wheel_link" > 
		<visual>
			<origin xyz="0 0 0" rpy="1.57 0 0"/>
			<geometry>
				<cylinder radius="0.033" length="0.026"/>
			</geometry>
		</visual>
		<collision>
			<origin xyz="0 0 0" rpy="1.57 0 0"/>
			<geometry>
				<cylinder radius="0.033" length="0.026"/>
			</geometry>
		</collision>
	</link>

	<!-- Joint con Rueda Derecha -->

	<joint name="wheel_right_joint" type="continuous"> 
		<parent link="base_link"/>
		<child link="right_wheel_link" />
		<origin xyz="0.15 -0.13 0"/>
		<axis xyz="0 1 0" />
	</joint>

	<!-- Rueda Izquierda -->

	<link name="left_wheel_link" > 
		<visual>
			<origin xyz="0 0 0" rpy="1.57 0 0"/>
			<geometry>
				<cylinder radius="0.033" length="0.026"/>
			</geometry>
		</visual>
		<collision>
			<origin xyz="0 0 0" rpy="1.57 0 0"/>
			<geometry>
				<cylinder radius="0.033" length="0.026"/>
			</geometry>
		</collision>
	</link>

	<joint name="wheel_left_joint" type="continuous"> 
		<parent link="base_link"/>
		<child link="left_wheel_link" />
		<origin xyz="0.15 0.13 0"/>
		<axis xyz="0 1 0" />
	</joint>



	<!-- Rueda Trasera  Derecha -->

	 <link name="caster_wheel_right_link" >
                <visual>
                        <origin xyz="0 0 0" rpy="1.57 0 0"/>
                        <geometry>
                                <cylinder radius="0.033" length="0.026"/>
                        </geometry>
                </visual>
                <collision>
                        <origin xyz="0 0 0" rpy="1.57 0 0"/>
                        <geometry>
                                <cylinder radius="0.033" length="0.026"/>
                        </geometry>
                </collision>
        </link>

        <joint name="right_wheel_caster_joint" type="fixed">
                <parent link="base_link"/>
                <child link="caster_wheel_right_link" />
                <origin xyz="-0.15 -0.13 0"/>
        </joint>


	<link name="caster_wheel_left_link" > 
		<visual>
			<origin xyz="0 0 0" rpy="1.57 0 0"/>
			<geometry>
				<cylinder radius="0.033" length="0.026"/>
			</geometry>
		</visual>
		<collision>
			<origin xyz="0 0 0" rpy="1.57 0 0"/>
			<geometry>
				<cylinder radius="0.033" length="0.026"/>
			</geometry>
		</collision>
	</link>

	<joint name="left_wheel_caster_joint" type="fixed"> 
		<parent link="base_link"/>
		<child link="caster_wheel_left_link" />
		<origin xyz="-0.15 0.13 0"/>
	</joint>
</robot>
